Workbook
Name Competition_Events: '（主催）種目リスト'!$B$2:$M$52
Name Entries: '(2)出場選手'!$B$2:$AB$103
Name Event_List: '（主催）設定・リスト'!$H$3:$J$73
Name Max_Entries: '（主催）設定・リスト'!$C$2
Name Max_Entry_Count: '（主催）設定・リスト'!$C$2
Name Prefectures: '（主催）設定・リスト'!$E$3:$E$50

Sheet （主催）カスタマイズマニュアル
A1: 【重要】
A2: このシートは「申込書テンプレートのカスタマイズ用マニュアル」です。
A3: 参加団体へ申込書として配布する前に、必ず本シートを削除してください。
A5: 本シートが残ったまま配布された申込書は、改ざんが発生する恐れがあるため、
A6: 申込書の正当性が担保できなくなってしまいます。
A7: ────────────────────────────────
A9: ■ この申込書テンプレートについて
A11: 本申込書は、記録情報処理担当者が
A12: ・申込を安全に回収し
A13: ・番組編成（スタートリスト作成）までを行うために設計されたテンプレートです。
A15: 「便利さ」よりも「事故を起こさないこと」を最優先しています。
A18: ■ このシートの目的
A20: 本シートは、
B21: ・記録情報処理担当者が大会ごとに設定すべき箇所
B22: ・編集してよい箇所／してはいけない箇所
B23: ・運用上の注意点
A24: を共有するための内部マニュアルです。
A26: 申込者（学校・クラブ・大学・個人）が読むことは想定していません。
A29: ■ 編集してよい箇所（主催者・処理担当者のみ）
A31: 以下は、大会ごとに必ず確認・設定してください。
A33: 【1】大会名・開催日
A34: ・表紙および鑑シートの表示項目を大会に合わせて変更する
A36: 【2】種目リスト（主催者設定シート）
B37: ・実施する種目の設定
B38: ・エントリー形式の設定
B39: ・エントリー料金の設定
B40: ・エントリー可能種目数の設定
A42: ※ 種目数を変更すると、出場選手シートの入力欄が
A43: 自動的に有効／無効（グレーアウト）されます。
A45: 【3】注意文言・案内文
B46: ・大会要項と整合する範囲で文言を変更してよい
B47: ・申込方法、注意事項の追加は可
A50: ■ 編集してはいけない箇所（重要）
A52: 以下の操作は禁止です。
B54: ・数式セルの編集
B55: ・列や行の削除・追加
B56: ・（自動）エントリー名簿シートの編集
B57: ・セルの並び替え
B58: ・マクロの追加
A60: これらを行うと、番組編成時に重大な不具合が発生します。
...

Sheet (1)鑑
B1: （競技会名）
B2: 参加申込書
B3: * は必ず記入すること。
B4: 申込団体
C5: 正式名称 | D5: * | E5: Orcheria Athlete Club
C6: 略称 （10文字以内 例:十日市小、みよしAC） | D6: * | E6: Orcheria
C7: チーム略称 / フリガナ （例: トオカイチショウ、ミヨシエーシー） | D7: * | E7: オルケリア
C8: 登録陸協 （大学は学連とすること） | D8: * | E8: 長崎県
C9: 所在地（住所） | D9: * | E9: 長崎県長崎市XX町XX X-XX-XXX
B10: 申込責任者
C11: 氏名（代表者等） | D11: * | E11: 空野 誠志郎
C12: 連絡先（代表連絡先） | D12: * | E12: 0953-XX-XXXX
B13: 引率者
C14: 氏名 | D14: * | E14: 空野 洋子
C15: 緊急連絡先 （当日連絡が取れる番号） | D15: * | E15: 0X0-XXXX-XXXX
B16: 派遣審判員（審判員資格は右に付記すること） | F16: 審判員資格
C17: 氏名１ | E17: 識辺 久菜 | F17: Ｂ
C18: 氏名２
C19: 氏名３
B21: 申込日 | D21: * | E21: 46209
B23: 本大会で登録した選手の個人情報並びに、選手を撮影した映像や画像等を本大会の要項記載の通り取り扱うことを承諾のうえ申し込みいたします。 | D23: * | E23: はい
B25: メールアドレス | D25: * | E25: office.orcheria@example.com
B27: 団体連絡欄（学校・クラブ共通）
B29: エントリー料金（数式による自動計算） | E29: =SUM('（自動）エントリー名簿'!$Q$3:$Q$503) -> 9000
B31: エントリー人数（数式による自動計算）
C32: 男子 | E32: =COUNTIF(OFFSET(Entries,0,1,,1),$C32) -> 0
C33: 女子 | E33: =COUNTIF(OFFSET(Entries,0,1,,1),$C33) -> 6
B35: 【申込について】
B36: ・ このファイルをそのままメールにて送付すること。
B37: ・ 申込控えとして本ファイルは申込者で保管すること。
B38: ・ 参加選手については「(2)出場選手」シートに記載すること。

Sheet (2)出場選手
B2: No. | C2: 性別 | D2: 登録番号 | E2: 姓 | F2: 名 | G2: カナ姓 | H2: カナ名 | I2: 学年 | J2: 所属 | K2: カナ所属 | L2: 登録陸協 | M2: 生年月日 | N2: 出場種目(1) | O2: 参考記録(1) | P2: エントリー備考(1) | Q2: 出場種目(2) | R2: 参考記録(2) | S2: エントリー備考(2) | T2: 出場種目(3) | U2: 参考記録(3) | V2: エントリー備考(3) | W2: 出場種目(4) | X2: 参考記録(4) | Y2: エントリー備考(4) | Z2: 出場種目(5) | AA2: 参考記録(5) | AB2: エントリー備考(5)
B3: =IF(OR(C3="",E3="", F3="", G3="", H3=""), "", MAX($B$2:OFFSET(B3, -1, 0))+1) -> 1 | C3: 女子 | D3: 8101 | E3: 空野 | F3: みなも | G3: ソラノ | H3: ミナモ | I3: 中2 | M3: 41093 | N3: 女子300mH | O3: 51.84 | Q3: 女子走幅跳 | R3: 5m18
B4: =IF(OR(C4="",E4="", F4="", G4="", H4=""), "", MAX($B$2:OFFSET(B4, -1, 0))+1) -> 2 | C4: 女子 | D4: 8102 | E4: 識辺 | F4: 佳賀里 | G4: シルベ | H4: カガリ | I4: 中2 | M4: 41129 | N4: 女子200m | O4: 26.82 | Q4: 女子400m | R4: 1:00.76
B5: =IF(OR(C5="",E5="", F5="", G5="", H5=""), "", MAX($B$2:OFFSET(B5, -1, 0))+1) -> 3 | C5: 女子 | D5: 8103 | E5: 一条 | F5: 流星 | G5: イチジョウ | H5: ナガセ | I5: 中1 | M5: 41568 | N5: 女子800m | O5: 2:19.26 | Q5: 女子1500m | R5: 4:35.13
B6: =IF(OR(C6="",E6="", F6="", G6="", H6=""), "", MAX($B$2:OFFSET(B6, -1, 0))+1) -> 4 | C6: 女子 | D6: 8104 | E6: 陽ノ下 | F6: 菜津 | G6: ヒノシタ | H6: ナツ | I6: 中1 | M6: 41222 | N6: 女子100m | O6: 13.27 | Q6: 女子棒高跳 | R6: 2m90
B7: =IF(OR(C7="",E7="", F7="", G7="", H7=""), "", MAX($B$2:OFFSET(B7, -1, 0))+1) -> 5 | C7: 女子 | D7: 8121 | E7: 風花 | F7: 菫 | G7: カザハナ | H7: スミレ | I7: 中3 | M7: 40960 | N7: 女子400m | O7: 57.97 | Q7: 女子1500m | R7: 4:37.22
B8: =IF(OR(C8="",E8="", F8="", G8="", H8=""), "", MAX($B$2:OFFSET(B8, -1, 0))+1) | C8: 女子
B9: =IF(OR(C9="",E9="", F9="", G9="", H9=""), "", MAX($B$2:OFFSET(B9, -1, 0))+1)
B10: =IF(OR(C10="",E10="", F10="", G10="", H10=""), "", MAX($B$2:OFFSET(B10, -1, 0))+1)
B11: =IF(OR(C11="",E11="", F11="", G11="", H11=""), "", MAX($B$2:OFFSET(B11, -1, 0))+1)
B12: =IF(OR(C12="",E12="", F12="", G12="", H12=""), "", MAX($B$2:OFFSET(B12, -1, 0))+1)
B13: =IF(OR(C13="",E13="", F13="", G13="", H13=""), "", MAX($B$2:OFFSET(B13, -1, 0))+1)
B14: =IF(OR(C14="",E14="", F14="", G14="", H14=""), "", MAX($B$2:OFFSET(B14, -1, 0))+1)
B15: =IF(OR(C15="",E15="", F15="", G15="", H15=""), "", MAX($B$2:OFFSET(B15, -1, 0))+1)
B16: =IF(OR(C16="",E16="", F16="", G16="", H16=""), "", MAX($B$2:OFFSET(B16, -1, 0))+1)
B17: =IF(OR(C17="",E17="", F17="", G17="", H17=""), "", MAX($B$2:OFFSET(B17, -1, 0))+1)
B18: =IF(OR(C18="",E18="", F18="", G18="", H18=""), "", MAX($B$2:OFFSET(B18, -1, 0))+1)
B19: =IF(OR(C19="",E19="", F19="", G19="", H19=""), "", MAX($B$2:OFFSET(B19, -1, 0))+1)
B20: =IF(OR(C20="",E20="", F20="", G20="", H20=""), "", MAX($B$2:OFFSET(B20, -1, 0))+1)
... B102: =IF(OR(C102="",E102="", F102="", G102="", H102=""), "", MAX($B$2:OFFSET(B102, -1, 0))+1)
B103: ▲▲▲▲ 表に収まりきらない場合は、これより上の行をコピーして複製すること。▲▲▲▲

Sheet （自動）エントリー名簿
B1: 12 | E1: 1 | F1: 2 | I1: 7 | J1: 8 | K1: 9 | L1: 10 | M1: 11 | N1: 12 | O1: 13 | P1: 14 | W1: 3 | X1: 4 | Y1: 5 | Z1: 6
D3: 名簿No. | E3: 性別 | F3: 登録番号 | G3: 競技者名 | H3: 競技者カナ名 | I3: 学年 | J3: 所属 | K3: 所属カナ | L3: 都道府県 | M3: 生年月日 | N3: 出場種目 | O3: 参考記録 | P3: エントリー備考 | Q3: エントリー料 | R3: 種目ID | S3: 種目種別 | T3: エントリー情報 | U3: 参考記録（数値）
A4: =TRUNC((ROWS($D$3:D4)-2)/Max_Entry_Count)+1 -> 1 | B4: =IF($A4>=ROWS(Entries)-2,"",IF(OFFSET('(2)出場選手'!$B$2,$A4,B$1+3*(MOD(ROWS($D$3:D4)-2,Max_Entry_Count)))="","",MOD(ROWS($D$3:D4)-2,Max_Entry_Count))) -> 0 | D4: =IF(OR($A4>=ROWS(Entries)-2,$B4=""),"",'(1)鑑'!$E$6&"-"&OFFSET('(2)出場選手'!$B$2,$A4,D$1)) -> Orcheria-1 | E4: =IF($D4="","",OFFSET('(2)出場選手'!$B$2,$A4,E$1)) -> 女子 | F4: =IF($D4="","",IF(OFFSET('(2)出場選手'!$B$2,$A4,F$1)="","",OFFSET('(2)出場選手'!$B$2,$A4,F$1))) -> 8101 | G4: =IF($D4="","",$W4&" "&$X4) -> 空野 みなも | H4: =IF($D4="","",ASC(TRIM($Y4)&" "&TRIM($Z4))) -> ｿﾗﾉ ﾐﾅﾓ | I4: =IF($D4="","",IF(OFFSET('(2)出場選手'!$B$2,$A4,I$1)="","",OFFSET('(2)出場選手'!$B$2,$A4,I$1))) -> 中2 | J4: =IF($D4="","",IF(OFFSET('(2)出場選手'!$B$2,$A4,J$1)="",'(1)鑑'!$E$6,OFFSET('(2)出場選手'!$B$2,$A4,J$1))) -> Orcheria | K4: =IF($D4="","",TRIM(ASC(IF(OFFSET('(2)出場選手'!$B$2,$A4,K$1)="",'(1)鑑'!$E$7,OFFSET('(2)出場選手'!$B$2,$A4,K$1))))) -> ｵﾙｹﾘｱ | L4: =IF($D4="","",SUBSTITUTE(SUBSTITUTE(SUBSTITUTE(IF(OFFSET('(2)出場選手'!$B$2,$A4,L$1)="",'(1)鑑'!$E$8,OFFSET('(2)出場選手'!$B$2,$A4,L$1)),"県",""),"府",""),"東京都","東京")) -> 長崎 | M4: =IF($D4="","",IF(OFFSET('(2)出場選手'!$B$2,$A4,M$1)="","",OFFSET('(2)出場選手'!$B$2,$A4,M$1))) -> 41093 | N4: =IF($D4="","",OFFSET('(2)出場選手'!$B$2,$A4,N$1+3*$B4)) -> 女子300mH | O4: =IF($D4="","",IF(OFFSET('(2)出場選手'!$B$2,$A4,O$1+3*$B4)="","",OFFSET('(2)出場選手'!$B$2,$A4,O$1+3*$B4))) -> 51.84 | P4: =IF($D4="","",IF(OFFSET('(2)出場選手'!$B$2,$A4,P$1+3*$B4)="","",OFFSET('(2)出場選手'!$B$2,$A4,P$1+3*$B4))) | Q4: =IF(D4="","",VLOOKUP(N4,OFFSET(Competition_Events,0,1),11,FALSE)*IF($S4="リレー",IF(COUNTIF($T$3:$T4,$T4)>1,0,1),1)) -> 900 | R4: =IF($D4="","",VLOOKUP($N4,OFFSET(Competition_Events,0,1),3,FALSE)) -> 21 | S4: =IF($D4="","",VLOOKUP($R4,Competition_Events,7,FALSE)) -> トラック | T4: =IF($D4="","",$N4&"//"&$P4) -> 女子300mH// | U4: =IF($D4="","",IFERROR(CHOOSE(VLOOKUP($R4,Competition_Events,6,FALSE),SUBSTITUTE(O4,"点","")*1,SUBSTITUTE(O4,"m",".")*100,SUBSTITUTE(SUBSTITUTE("0:"&O4,"'",":"),"""",".")/"0:00:00.01"*-1,SUBSTITUTE(O4,"m",".")*100,SUBSTITUTE(SUBSTITUTE(O4,"'",":"),"""",".")/"0:00:00.01"*-1),-8640000)) -> -5184 | W4: =IF($D4="","",OFFSET('(2)出場選手'!$B$2,$A4,W$1)) -> 空野 | X4: =IF($D4="","",OFFSET('(2)出場選手'!$B$2,$A4,X$1)) -> みなも | Y4: =IF($D4="","",OFFSET('(2)出場選手'!$B$2,$A4,Y$1)) -> ソラノ | Z4: =IF($D4="","",OFFSET('(2)出場選手'!$B$2,$A4,Z$1)) -> ミナモ
A5: =TRUNC((ROWS($D$3:D5)-2)/Max_Entry_Count)+1 -> 1 | B5: =IF($A5>=ROWS(Entries)-2,"",IF(OFFSET('(2)出場選手'!$B$2,$A5,B$1+3*(MOD(ROWS($D$3:D5)-2,Max_Entry_Count)))="","",MOD(ROWS($D$3:D5)-2,Max_Entry_Count))) -> 1 | D5: =IF(OR($A5>=ROWS(Entries)-2,$B5=""),"",'(1)鑑'!$E$6&"-"&OFFSET('(2)出場選手'!$B$2,$A5,D$1)) -> Orcheria-1 | E5: =IF($D5="","",OFFSET('(2)出場選手'!$B$2,$A5,E$1)) -> 女子 | F5: =IF($D5="","",IF(OFFSET('(2)出場選手'!$B$2,$A5,F$1)="","",OFFSET('(2)出場選手'!$B$2,$A5,F$1))) -> 8101 | G5: =IF($D5="","",$W5&" "&$X5) -> 空野 みなも | H5: =IF($D5="","",ASC(TRIM($Y5)&" "&TRIM($Z5))) -> ｿﾗﾉ ﾐﾅﾓ | I5: =IF($D5="","",IF(OFFSET('(2)出場選手'!$B$2,$A5,I$1)="","",OFFSET('(2)出場選手'!$B$2,$A5,I$1))) -> 中2 | J5: =IF($D5="","",IF(OFFSET('(2)出場選手'!$B$2,$A5,J$1)="",'(1)鑑'!$E$6,OFFSET('(2)出場選手'!$B$2,$A5,J$1))) -> Orcheria | K5: =IF($D5="","",TRIM(ASC(IF(OFFSET('(2)出場選手'!$B$2,$A5,K$1)="",'(1)鑑'!$E$7,OFFSET('(2)出場選手'!$B$2,$A5,K$1))))) -> ｵﾙｹﾘｱ | L5: =IF($D5="","",SUBSTITUTE(SUBSTITUTE(SUBSTITUTE(IF(OFFSET('(2)出場選手'!$B$2,$A5,L$1)="",'(1)鑑'!$E$8,OFFSET('(2)出場選手'!$B$2,$A5,L$1)),"県",""),"府",""),"東京都","東京")) -> 長崎 | M5: =IF($D5="","",IF(OFFSET('(2)出場選手'!$B$2,$A5,M$1)="","",OFFSET('(2)出場選手'!$B$2,$A5,M$1))) -> 41093 | N5: =IF($D5="","",OFFSET('(2)出場選手'!$B$2,$A5,N$1+3*$B5)) -> 女子走幅跳 | O5: =IF($D5="","",IF(OFFSET('(2)出場選手'!$B$2,$A5,O$1+3*$B5)="","",OFFSET('(2)出場選手'!$B$2,$A5,O$1+3*$B5))) -> 5m18 | P5: =IF($D5="","",IF(OFFSET('(2)出場選手'!$B$2,$A5,P$1+3*$B5)="","",OFFSET('(2)出場選手'!$B$2,$A5,P$1+3*$B5))) | Q5: =IF(D5="","",VLOOKUP(N5,OFFSET(Competition_Events,0,1),11,FALSE)*IF($S5="リレー",IF(COUNTIF($T$3:$T5,$T5)>1,0,1),1)) -> 900 | R5: =IF($D5="","",VLOOKUP($N5,OFFSET(Competition_Events,0,1),3,FALSE)) -> 25 | S5: =IF($D5="","",VLOOKUP($R5,Competition_Events,7,FALSE)) -> フィールド | T5: =IF($D5="","",$N5&"//"&$P5) -> 女子走幅跳// | U5: =IF($D5="","",IFERROR(CHOOSE(VLOOKUP($R5,Competition_Events,6,FALSE),SUBSTITUTE(O5,"点","")*1,SUBSTITUTE(O5,"m",".")*100,SUBSTITUTE(SUBSTITUTE("0:"&O5,"'",":"),"""",".")/"0:00:00.01"*-1,SUBSTITUTE(O5,"m",".")*100,SUBSTITUTE(SUBSTITUTE(O5,"'",":"),"""",".")/"0:00:00.01"*-1),-8640000)) -> 518 | W5: =IF($D5="","",OFFSET('(2)出場選手'!$B$2,$A5,W$1)) -> 空野 | X5: =IF($D5="","",OFFSET('(2)出場選手'!$B$2,$A5,X$1)) -> みなも | Y5: =IF($D5="","",OFFSET('(2)出場選手'!$B$2,$A5,Y$1)) -> ソラノ | Z5: =IF($D5="","",OFFSET('(2)出場選手'!$B$2,$A5,Z$1)) -> ミナモ
A6: =TRUNC((ROWS($D$3:D6)-2)/Max_Entry_Count)+1 -> 1 | B6: =IF($A6>=ROWS(Entries)-2,"",IF(OFFSET('(2)出場選手'!$B$2,$A6,B$1+3*(MOD(ROWS($D$3:D6)-2,Max_Entry_Count)))="","",MOD(ROWS($D$3:D6)-2,Max_Entry_Count))) | D6: =IF(OR($A6>=ROWS(Entries)-2,$B6=""),"",'(1)鑑'!$E$6&"-"&OFFSET('(2)出場選手'!$B$2,$A6,D$1)) | E6: =IF($D6="","",OFFSET('(2)出場選手'!$B$2,$A6,E$1)) | F6: =IF($D6="","",IF(OFFSET('(2)出場選手'!$B$2,$A6,F$1)="","",OFFSET('(2)出場選手'!$B$2,$A6,F$1))) | G6: =IF($D6="","",$W6&" "&$X6) | H6: =IF($D6="","",ASC(TRIM($Y6)&" "&TRIM($Z6))) | I6: =IF($D6="","",IF(OFFSET('(2)出場選手'!$B$2,$A6,I$1)="","",OFFSET('(2)出場選手'!$B$2,$A6,I$1))) | J6: =IF($D6="","",IF(OFFSET('(2)出場選手'!$B$2,$A6,J$1)="",'(1)鑑'!$E$6,OFFSET('(2)出場選手'!$B$2,$A6,J$1))) | K6: =IF($D6="","",TRIM(ASC(IF(OFFSET('(2)出場選手'!$B$2,$A6,K$1)="",'(1)鑑'!$E$7,OFFSET('(2)出場選手'!$B$2,$A6,K$1))))) | L6: =IF($D6="","",SUBSTITUTE(SUBSTITUTE(SUBSTITUTE(IF(OFFSET('(2)出場選手'!$B$2,$A6,L$1)="",'(1)鑑'!$E$8,OFFSET('(2)出場選手'!$B$2,$A6,L$1)),"県",""),"府",""),"東京都","東京")) | M6: =IF($D6="","",IF(OFFSET('(2)出場選手'!$B$2,$A6,M$1)="","",OFFSET('(2)出場選手'!$B$2,$A6,M$1))) | N6: =IF($D6="","",OFFSET('(2)出場選手'!$B$2,$A6,N$1+3*$B6)) | O6: =IF($D6="","",IF(OFFSET('(2)出場選手'!$B$2,$A6,O$1+3*$B6)="","",OFFSET('(2)出場選手'!$B$2,$A6,O$1+3*$B6))) | P6: =IF($D6="","",IF(OFFSET('(2)出場選手'!$B$2,$A6,P$1+3*$B6)="","",OFFSET('(2)出場選手'!$B$2,$A6,P$1+3*$B6))) | Q6: =IF(D6="","",VLOOKUP(N6,OFFSET(Competition_Events,0,1),11,FALSE)*IF($S6="リレー",IF(COUNTIF($T$3:$T6,$T6)>1,0,1),1)) | R6: =IF($D6="","",VLOOKUP($N6,OFFSET(Competition_Events,0,1),3,FALSE)) | S6: =IF($D6="","",VLOOKUP($R6,Competition_Events,7,FALSE)) | T6: =IF($D6="","",$N6&"//"&$P6) | U6: =IF($D6="","",IFERROR(CHOOSE(VLOOKUP($R6,Competition_Events,6,FALSE),SUBSTITUTE(O6,"点","")*1,SUBSTITUTE(O6,"m",".")*100,SUBSTITUTE(SUBSTITUTE("0:"&O6,"'",":"),"""",".")/"0:00:00.01"*-1,SUBSTITUTE(O6,"m",".")*100,SUBSTITUTE(SUBSTITUTE(O6,"'",":"),"""",".")/"0:00:00.01"*-1),-8640000)) | W6: =IF($D6="","",OFFSET('(2)出場選手'!$B$2,$A6,W$1)) | X6: =IF($D6="","",OFFSET('(2)出場選手'!$B$2,$A6,X$1)) | Y6: =IF($D6="","",OFFSET('(2)出場選手'!$B$2,$A6,Y$1)) | Z6: =IF($D6="","",OFFSET('(2)出場選手'!$B$2,$A6,Z$1))
A7: =TRUNC((ROWS($D$3:D7)-2)/Max_Entry_Count)+1 -> 2 | B7: =IF($A7>=ROWS(Entries)-2,"",IF(OFFSET('(2)出場選手'!$B$2,$A7,B$1+3*(MOD(ROWS($D$3:D7)-2,Max_Entry_Count)))="","",MOD(ROWS($D$3:D7)-2,Max_Entry_Count))) -> 0 | D7: =IF(OR($A7>=ROWS(Entries)-2,$B7=""),"",'(1)鑑'!$E$6&"-"&OFFSET('(2)出場選手'!$B$2,$A7,D$1)) -> Orcheria-2 | E7: =IF($D7="","",OFFSET('(2)出場選手'!$B$2,$A7,E$1)) -> 女子 | F7: =IF($D7="","",IF(OFFSET('(2)出場選手'!$B$2,$A7,F$1)="","",OFFSET('(2)出場選手'!$B$2,$A7,F$1))) -> 8102 | G7: =IF($D7="","",$W7&" "&$X7) -> 識辺 佳賀里 | H7: =IF($D7="","",ASC(TRIM($Y7)&" "&TRIM($Z7))) -> ｼﾙﾍﾞ ｶｶﾞﾘ | I7: =IF($D7="","",IF(OFFSET('(2)出場選手'!$B$2,$A7,I$1)="","",OFFSET('(2)出場選手'!$B$2,$A7,I$1))) -> 中2 | J7: =IF($D7="","",IF(OFFSET('(2)出場選手'!$B$2,$A7,J$1)="",'(1)鑑'!$E$6,OFFSET('(2)出場選手'!$B$2,$A7,J$1))) -> Orcheria | K7: =IF($D7="","",TRIM(ASC(IF(OFFSET('(2)出場選手'!$B$2,$A7,K$1)="",'(1)鑑'!$E$7,OFFSET('(2)出場選手'!$B$2,$A7,K$1))))) -> ｵﾙｹﾘｱ | L7: =IF($D7="","",SUBSTITUTE(SUBSTITUTE(SUBSTITUTE(IF(OFFSET('(2)出場選手'!$B$2,$A7,L$1)="",'(1)鑑'!$E$8,OFFSET('(2)出場選手'!$B$2,$A7,L$1)),"県",""),"府",""),"東京都","東京")) -> 長崎 | M7: =IF($D7="","",IF(OFFSET('(2)出場選手'!$B$2,$A7,M$1)="","",OFFSET('(2)出場選手'!$B$2,$A7,M$1))) -> 41129 | N7: =IF($D7="","",OFFSET('(2)出場選手'!$B$2,$A7,N$1+3*$B7)) -> 女子200m | O7: =IF($D7="","",IF(OFFSET('(2)出場選手'!$B$2,$A7,O$1+3*$B7)="","",OFFSET('(2)出場選手'!$B$2,$A7,O$1+3*$B7))) -> 26.82 | P7: =IF($D7="","",IF(OFFSET('(2)出場選手'!$B$2,$A7,P$1+3*$B7)="","",OFFSET('(2)出場選手'!$B$2,$A7,P$1+3*$B7))) | Q7: =IF(D7="","",VLOOKUP(N7,OFFSET(Competition_Events,0,1),11,FALSE)*IF($S7="リレー",IF(COUNTIF($T$3:$T7,$T7)>1,0,1),1)) -> 900 | R7: =IF($D7="","",VLOOKUP($N7,OFFSET(Competition_Events,0,1),3,FALSE)) -> 16 | S7: =IF($D7="","",VLOOKUP($R7,Competition_Events,7,FALSE)) -> トラック | T7: =IF($D7="","",$N7&"//"&$P7) -> 女子200m// | U7: =IF($D7="","",IFERROR(CHOOSE(VLOOKUP($R7,Competition_Events,6,FALSE),SUBSTITUTE(O7,"点","")*1,SUBSTITUTE(O7,"m",".")*100,SUBSTITUTE(SUBSTITUTE("0:"&O7,"'",":"),"""",".")/"0:00:00.01"*-1,SUBSTITUTE(O7,"m",".")*100,SUBSTITUTE(SUBSTITUTE(O7,"'",":"),"""",".")/"0:00:00.01"*-1),-8640000)) -> -2682 | W7: =IF($D7="","",OFFSET('(2)出場選手'!$B$2,$A7,W$1)) -> 識辺 | X7: =IF($D7="","",OFFSET('(2)出場選手'!$B$2,$A7,X$1)) -> 佳賀里 | Y7: =IF($D7="","",OFFSET('(2)出場選手'!$B$2,$A7,Y$1)) -> シルベ | Z7: =IF($D7="","",OFFSET('(2)出場選手'!$B$2,$A7,Z$1)) -> カガリ
A8: =TRUNC((ROWS($D$3:D8)-2)/Max_Entry_Count)+1 -> 2 | B8: =IF($A8>=ROWS(Entries)-2,"",IF(OFFSET('(2)出場選手'!$B$2,$A8,B$1+3*(MOD(ROWS($D$3:D8)-2,Max_Entry_Count)))="","",MOD(ROWS($D$3:D8)-2,Max_Entry_Count))) -> 1 | D8: =IF(OR($A8>=ROWS(Entries)-2,$B8=""),"",'(1)鑑'!$E$6&"-"&OFFSET('(2)出場選手'!$B$2,$A8,D$1)) -> Orcheria-2 | E8: =IF($D8="","",OFFSET('(2)出場選手'!$B$2,$A8,E$1)) -> 女子 | F8: =IF($D8="","",IF(OFFSET('(2)出場選手'!$B$2,$A8,F$1)="","",OFFSET('(2)出場選手'!$B$2,$A8,F$1))) -> 8102 | G8: =IF($D8="","",$W8&" "&$X8) -> 識辺 佳賀里 | H8: =IF($D8="","",ASC(TRIM($Y8)&" "&TRIM($Z8))) -> ｼﾙﾍﾞ ｶｶﾞﾘ | I8: =IF($D8="","",IF(OFFSET('(2)出場選手'!$B$2,$A8,I$1)="","",OFFSET('(2)出場選手'!$B$2,$A8,I$1))) -> 中2 | J8: =IF($D8="","",IF(OFFSET('(2)出場選手'!$B$2,$A8,J$1)="",'(1)鑑'!$E$6,OFFSET('(2)出場選手'!$B$2,$A8,J$1))) -> Orcheria | K8: =IF($D8="","",TRIM(ASC(IF(OFFSET('(2)出場選手'!$B$2,$A8,K$1)="",'(1)鑑'!$E$7,OFFSET('(2)出場選手'!$B$2,$A8,K$1))))) -> ｵﾙｹﾘｱ | L8: =IF($D8="","",SUBSTITUTE(SUBSTITUTE(SUBSTITUTE(IF(OFFSET('(2)出場選手'!$B$2,$A8,L$1)="",'(1)鑑'!$E$8,OFFSET('(2)出場選手'!$B$2,$A8,L$1)),"県",""),"府",""),"東京都","東京")) -> 長崎 | M8: =IF($D8="","",IF(OFFSET('(2)出場選手'!$B$2,$A8,M$1)="","",OFFSET('(2)出場選手'!$B$2,$A8,M$1))) -> 41129 | N8: =IF($D8="","",OFFSET('(2)出場選手'!$B$2,$A8,N$1+3*$B8)) -> 女子400m | O8: =IF($D8="","",IF(OFFSET('(2)出場選手'!$B$2,$A8,O$1+3*$B8)="","",OFFSET('(2)出場選手'!$B$2,$A8,O$1+3*$B8))) -> 1:00.76 | P8: =IF($D8="","",IF(OFFSET('(2)出場選手'!$B$2,$A8,P$1+3*$B8)="","",OFFSET('(2)出場選手'!$B$2,$A8,P$1+3*$B8))) | Q8: =IF(D8="","",VLOOKUP(N8,OFFSET(Competition_Events,0,1),11,FALSE)*IF($S8="リレー",IF(COUNTIF($T$3:$T8,$T8)>1,0,1),1)) -> 900 | R8: =IF($D8="","",VLOOKUP($N8,OFFSET(Competition_Events,0,1),3,FALSE)) -> 17 | S8: =IF($D8="","",VLOOKUP($R8,Competition_Events,7,FALSE)) -> トラック | T8: =IF($D8="","",$N8&"//"&$P8) -> 女子400m// | U8: =IF($D8="","",IFERROR(CHOOSE(VLOOKUP($R8,Competition_Events,6,FALSE),SUBSTITUTE(O8,"点","")*1,SUBSTITUTE(O8,"m",".")*100,SUBSTITUTE(SUBSTITUTE("0:"&O8,"'",":"),"""",".")/"0:00:00.01"*-1,SUBSTITUTE(O8,"m",".")*100,SUBSTITUTE(SUBSTITUTE(O8,"'",":"),"""",".")/"0:00:00.01"*-1),-8640000)) -> -6076 | W8: =IF($D8="","",OFFSET('(2)出場選手'!$B$2,$A8,W$1)) -> 識辺 | X8: =IF($D8="","",OFFSET('(2)出場選手'!$B$2,$A8,X$1)) -> 佳賀里 | Y8: =IF($D8="","",OFFSET('(2)出場選手'!$B$2,$A8,Y$1)) -> シルベ | Z8: =IF($D8="","",OFFSET('(2)出場選手'!$B$2,$A8,Z$1)) -> カガリ
A9: =TRUNC((ROWS($D$3:D9)-2)/Max_Entry_Count)+1 -> 2 | B9: =IF($A9>=ROWS(Entries)-2,"",IF(OFFSET('(2)出場選手'!$B$2,$A9,B$1+3*(MOD(ROWS($D$3:D9)-2,Max_Entry_Count)))="","",MOD(ROWS($D$3:D9)-2,Max_Entry_Count))) | D9: =IF(OR($A9>=ROWS(Entries)-2,$B9=""),"",'(1)鑑'!$E$6&"-"&OFFSET('(2)出場選手'!$B$2,$A9,D$1)) | E9: =IF($D9="","",OFFSET('(2)出場選手'!$B$2,$A9,E$1)) | F9: =IF($D9="","",IF(OFFSET('(2)出場選手'!$B$2,$A9,F$1)="","",OFFSET('(2)出場選手'!$B$2,$A9,F$1))) | G9: =IF($D9="","",$W9&" "&$X9) | H9: =IF($D9="","",ASC(TRIM($Y9)&" "&TRIM($Z9))) | I9: =IF($D9="","",IF(OFFSET('(2)出場選手'!$B$2,$A9,I$1)="","",OFFSET('(2)出場選手'!$B$2,$A9,I$1))) | J9: =IF($D9="","",IF(OFFSET('(2)出場選手'!$B$2,$A9,J$1)="",'(1)鑑'!$E$6,OFFSET('(2)出場選手'!$B$2,$A9,J$1))) | K9: =IF($D9="","",TRIM(ASC(IF(OFFSET('(2)出場選手'!$B$2,$A9,K$1)="",'(1)鑑'!$E$7,OFFSET('(2)出場選手'!$B$2,$A9,K$1))))) | L9: =IF($D9="","",SUBSTITUTE(SUBSTITUTE(SUBSTITUTE(IF(OFFSET('(2)出場選手'!$B$2,$A9,L$1)="",'(1)鑑'!$E$8,OFFSET('(2)出場選手'!$B$2,$A9,L$1)),"県",""),"府",""),"東京都","東京")) | M9: =IF($D9="","",IF(OFFSET('(2)出場選手'!$B$2,$A9,M$1)="","",OFFSET('(2)出場選手'!$B$2,$A9,M$1))) | N9: =IF($D9="","",OFFSET('(2)出場選手'!$B$2,$A9,N$1+3*$B9)) | O9: =IF($D9="","",IF(OFFSET('(2)出場選手'!$B$2,$A9,O$1+3*$B9)="","",OFFSET('(2)出場選手'!$B$2,$A9,O$1+3*$B9))) | P9: =IF($D9="","",IF(OFFSET('(2)出場選手'!$B$2,$A9,P$1+3*$B9)="","",OFFSET('(2)出場選手'!$B$2,$A9,P$1+3*$B9))) | Q9: =IF(D9="","",VLOOKUP(N9,OFFSET(Competition_Events,0,1),11,FALSE)*IF($S9="リレー",IF(COUNTIF($T$3:$T9,$T9)>1,0,1),1)) | R9: =IF($D9="","",VLOOKUP($N9,OFFSET(Competition_Events,0,1),3,FALSE)) | S9: =IF($D9="","",VLOOKUP($R9,Competition_Events,7,FALSE)) | T9: =IF($D9="","",$N9&"//"&$P9) | U9: =IF($D9="","",IFERROR(CHOOSE(VLOOKUP($R9,Competition_Events,6,FALSE),SUBSTITUTE(O9,"点","")*1,SUBSTITUTE(O9,"m",".")*100,SUBSTITUTE(SUBSTITUTE("0:"&O9,"'",":"),"""",".")/"0:00:00.01"*-1,SUBSTITUTE(O9,"m",".")*100,SUBSTITUTE(SUBSTITUTE(O9,"'",":"),"""",".")/"0:00:00.01"*-1),-8640000)) | W9: =IF($D9="","",OFFSET('(2)出場選手'!$B$2,$A9,W$1)) | X9: =IF($D9="","",OFFSET('(2)出場選手'!$B$2,$A9,X$1)) | Y9: =IF($D9="","",OFFSET('(2)出場選手'!$B$2,$A9,Y$1)) | Z9: =IF($D9="","",OFFSET('(2)出場選手'!$B$2,$A9,Z$1))
A10: =TRUNC((ROWS($D$3:D10)-2)/Max_Entry_Count)+1 -> 3 | B10: =IF($A10>=ROWS(Entries)-2,"",IF(OFFSET('(2)出場選手'!$B$2,$A10,B$1+3*(MOD(ROWS($D$3:D10)-2,Max_Entry_Count)))="","",MOD(ROWS($D$3:D10)-2,Max_Entry_Count))) -> 0 | D10: =IF(OR($A10>=ROWS(Entries)-2,$B10=""),"",'(1)鑑'!$E$6&"-"&OFFSET('(2)出場選手'!$B$2,$A10,D$1)) -> Orcheria-3 | E10: =IF($D10="","",OFFSET('(2)出場選手'!$B$2,$A10,E$1)) -> 女子 | F10: =IF($D10="","",IF(OFFSET('(2)出場選手'!$B$2,$A10,F$1)="","",OFFSET('(2)出場選手'!$B$2,$A10,F$1))) -> 8103 | G10: =IF($D10="","",$W10&" "&$X10) -> 一条 流星 | H10: =IF($D10="","",ASC(TRIM($Y10)&" "&TRIM($Z10))) -> ｲﾁｼﾞｮｳ ﾅｶﾞｾ | I10: =IF($D10="","",IF(OFFSET('(2)出場選手'!$B$2,$A10,I$1)="","",OFFSET('(2)出場選手'!$B$2,$A10,I$1))) -> 中1 | J10: =IF($D10="","",IF(OFFSET('(2)出場選手'!$B$2,$A10,J$1)="",'(1)鑑'!$E$6,OFFSET('(2)出場選手'!$B$2,$A10,J$1))) -> Orcheria | K10: =IF($D10="","",TRIM(ASC(IF(OFFSET('(2)出場選手'!$B$2,$A10,K$1)="",'(1)鑑'!$E$7,OFFSET('(2)出場選手'!$B$2,$A10,K$1))))) -> ｵﾙｹﾘｱ | L10: =IF($D10="","",SUBSTITUTE(SUBSTITUTE(SUBSTITUTE(IF(OFFSET('(2)出場選手'!$B$2,$A10,L$1)="",'(1)鑑'!$E$8,OFFSET('(2)出場選手'!$B$2,$A10,L$1)),"県",""),"府",""),"東京都","東京")) -> 長崎 | M10: =IF($D10="","",IF(OFFSET('(2)出場選手'!$B$2,$A10,M$1)="","",OFFSET('(2)出場選手'!$B$2,$A10,M$1))) -> 41568 | N10: =IF($D10="","",OFFSET('(2)出場選手'!$B$2,$A10,N$1+3*$B10)) -> 女子800m | O10: =IF($D10="","",IF(OFFSET('(2)出場選手'!$B$2,$A10,O$1+3*$B10)="","",OFFSET('(2)出場選手'!$B$2,$A10,O$1+3*$B10))) -> 2:19.26 | P10: =IF($D10="","",IF(OFFSET('(2)出場選手'!$B$2,$A10,P$1+3*$B10)="","",OFFSET('(2)出場選手'!$B$2,$A10,P$1+3*$B10))) | Q10: =IF(D10="","",VLOOKUP(N10,OFFSET(Competition_Events,0,1),11,FALSE)*IF($S10="リレー",IF(COUNTIF($T$3:$T10,$T10)>1,0,1),1)) -> 900 | R10: =IF($D10="","",VLOOKUP($N10,OFFSET(Competition_Events,0,1),3,FALSE)) -> 18 | S10: =IF($D10="","",VLOOKUP($R10,Competition_Events,7,FALSE)) -> トラック | T10: =IF($D10="","",$N10&"//"&$P10) -> 女子800m// | U10: =IF($D10="","",IFERROR(CHOOSE(VLOOKUP($R10,Competition_Events,6,FALSE),SUBSTITUTE(O10,"点","")*1,SUBSTITUTE(O10,"m",".")*100,SUBSTITUTE(SUBSTITUTE("0:"&O10,"'",":"),"""",".")/"0:00:00.01"*-1,SUBSTITUTE(O10,"m",".")*100,SUBSTITUTE(SUBSTITUTE(O10,"'",":"),"""",".")/"0:00:00.01"*-1),-8640000)) -> -13926 | W10: =IF($D10="","",OFFSET('(2)出場選手'!$B$2,$A10,W$1)) -> 一条 | X10: =IF($D10="","",OFFSET('(2)出場選手'!$B$2,$A10,X$1)) -> 流星 | Y10: =IF($D10="","",OFFSET('(2)出場選手'!$B$2,$A10,Y$1)) -> イチジョウ | Z10: =IF($D10="","",OFFSET('(2)出場選手'!$B$2,$A10,Z$1)) -> ナガセ
A11: =TRUNC((ROWS($D$3:D11)-2)/Max_Entry_Count)+1 -> 3 | B11: =IF($A11>=ROWS(Entries)-2,"",IF(OFFSET('(2)出場選手'!$B$2,$A11,B$1+3*(MOD(ROWS($D$3:D11)-2,Max_Entry_Count)))="","",MOD(ROWS($D$3:D11)-2,Max_Entry_Count))) -> 1 | D11: =IF(OR($A11>=ROWS(Entries)-2,$B11=""),"",'(1)鑑'!$E$6&"-"&OFFSET('(2)出場選手'!$B$2,$A11,D$1)) -> Orcheria-3 | E11: =IF($D11="","",OFFSET('(2)出場選手'!$B$2,$A11,E$1)) -> 女子 | F11: =IF($D11="","",IF(OFFSET('(2)出場選手'!$B$2,$A11,F$1)="","",OFFSET('(2)出場選手'!$B$2,$A11,F$1))) -> 8103 | G11: =IF($D11="","",$W11&" "&$X11) -> 一条 流星 | H11: =IF($D11="","",ASC(TRIM($Y11)&" "&TRIM($Z11))) -> ｲﾁｼﾞｮｳ ﾅｶﾞｾ | I11: =IF($D11="","",IF(OFFSET('(2)出場選手'!$B$2,$A11,I$1)="","",OFFSET('(2)出場選手'!$B$2,$A11,I$1))) -> 中1 | J11: =IF($D11="","",IF(OFFSET('(2)出場選手'!$B$2,$A11,J$1)="",'(1)鑑'!$E$6,OFFSET('(2)出場選手'!$B$2,$A11,J$1))) -> Orcheria | K11: =IF($D11="","",TRIM(ASC(IF(OFFSET('(2)出場選手'!$B$2,$A11,K$1)="",'(1)鑑'!$E$7,OFFSET('(2)出場選手'!$B$2,$A11,K$1))))) -> ｵﾙｹﾘｱ | L11: =IF($D11="","",SUBSTITUTE(SUBSTITUTE(SUBSTITUTE(IF(OFFSET('(2)出場選手'!$B$2,$A11,L$1)="",'(1)鑑'!$E$8,OFFSET('(2)出場選手'!$B$2,$A11,L$1)),"県",""),"府",""),"東京都","東京")) -> 長崎 | M11: =IF($D11="","",IF(OFFSET('(2)出場選手'!$B$2,$A11,M$1)="","",OFFSET('(2)出場選手'!$B$2,$A11,M$1))) -> 41568 | N11: =IF($D11="","",OFFSET('(2)出場選手'!$B$2,$A11,N$1+3*$B11)) -> 女子1500m | O11: =IF($D11="","",IF(OFFSET('(2)出場選手'!$B$2,$A11,O$1+3*$B11)="","",OFFSET('(2)出場選手'!$B$2,$A11,O$1+3*$B11))) -> 4:35.13 | P11: =IF($D11="","",IF(OFFSET('(2)出場選手'!$B$2,$A11,P$1+3*$B11)="","",OFFSET('(2)出場選手'!$B$2,$A11,P$1+3*$B11))) | Q11: =IF(D11="","",VLOOKUP(N11,OFFSET(Competition_Events,0,1),11,FALSE)*IF($S11="リレー",IF(COUNTIF($T$3:$T11,$T11)>1,0,1),1)) -> 900 | R11: =IF($D11="","",VLOOKUP($N11,OFFSET(Competition_Events,0,1),3,FALSE)) -> 19 | S11: =IF($D11="","",VLOOKUP($R11,Competition_Events,7,FALSE)) -> トラック | T11: =IF($D11="","",$N11&"//"&$P11) -> 女子1500m// | U11: =IF($D11="","",IFERROR(CHOOSE(VLOOKUP($R11,Competition_Events,6,FALSE),SUBSTITUTE(O11,"点","")*1,SUBSTITUTE(O11,"m",".")*100,SUBSTITUTE(SUBSTITUTE("0:"&O11,"'",":"),"""",".")/"0:00:00.01"*-1,SUBSTITUTE(O11,"m",".")*100,SUBSTITUTE(SUBSTITUTE(O11,"'",":"),"""",".")/"0:00:00.01"*-1),-8640000)) -> -27513 | W11: =IF($D11="","",OFFSET('(2)出場選手'!$B$2,$A11,W$1)) -> 一条 | X11: =IF($D11="","",OFFSET('(2)出場選手'!$B$2,$A11,X$1)) -> 流星 | Y11: =IF($D11="","",OFFSET('(2)出場選手'!$B$2,$A11,Y$1)) -> イチジョウ | Z11: =IF($D11="","",OFFSET('(2)出場選手'!$B$2,$A11,Z$1)) -> ナガセ
A12: =TRUNC((ROWS($D$3:D12)-2)/Max_Entry_Count)+1 -> 3 | B12: =IF($A12>=ROWS(Entries)-2,"",IF(OFFSET('(2)出場選手'!$B$2,$A12,B$1+3*(MOD(ROWS($D$3:D12)-2,Max_Entry_Count)))="","",MOD(ROWS($D$3:D12)-2,Max_Entry_Count))) | D12: =IF(OR($A12>=ROWS(Entries)-2,$B12=""),"",'(1)鑑'!$E$6&"-"&OFFSET('(2)出場選手'!$B$2,$A12,D$1)) | E12: =IF($D12="","",OFFSET('(2)出場選手'!$B$2,$A12,E$1)) | F12: =IF($D12="","",IF(OFFSET('(2)出場選手'!$B$2,$A12,F$1)="","",OFFSET('(2)出場選手'!$B$2,$A12,F$1))) | G12: =IF($D12="","",$W12&" "&$X12) | H12: =IF($D12="","",ASC(TRIM($Y12)&" "&TRIM($Z12))) | I12: =IF($D12="","",IF(OFFSET('(2)出場選手'!$B$2,$A12,I$1)="","",OFFSET('(2)出場選手'!$B$2,$A12,I$1))) | J12: =IF($D12="","",IF(OFFSET('(2)出場選手'!$B$2,$A12,J$1)="",'(1)鑑'!$E$6,OFFSET('(2)出場選手'!$B$2,$A12,J$1))) | K12: =IF($D12="","",TRIM(ASC(IF(OFFSET('(2)出場選手'!$B$2,$A12,K$1)="",'(1)鑑'!$E$7,OFFSET('(2)出場選手'!$B$2,$A12,K$1))))) | L12: =IF($D12="","",SUBSTITUTE(SUBSTITUTE(SUBSTITUTE(IF(OFFSET('(2)出場選手'!$B$2,$A12,L$1)="",'(1)鑑'!$E$8,OFFSET('(2)出場選手'!$B$2,$A12,L$1)),"県",""),"府",""),"東京都","東京")) | M12: =IF($D12="","",IF(OFFSET('(2)出場選手'!$B$2,$A12,M$1)="","",OFFSET('(2)出場選手'!$B$2,$A12,M$1))) | N12: =IF($D12="","",OFFSET('(2)出場選手'!$B$2,$A12,N$1+3*$B12)) | O12: =IF($D12="","",IF(OFFSET('(2)出場選手'!$B$2,$A12,O$1+3*$B12)="","",OFFSET('(2)出場選手'!$B$2,$A12,O$1+3*$B12))) | P12: =IF($D12="","",IF(OFFSET('(2)出場選手'!$B$2,$A12,P$1+3*$B12)="","",OFFSET('(2)出場選手'!$B$2,$A12,P$1+3*$B12))) | Q12: =IF(D12="","",VLOOKUP(N12,OFFSET(Competition_Events,0,1),11,FALSE)*IF($S12="リレー",IF(COUNTIF($T$3:$T12,$T12)>1,0,1),1)) | R12: =IF($D12="","",VLOOKUP($N12,OFFSET(Competition_Events,0,1),3,FALSE)) | S12: =IF($D12="","",VLOOKUP($R12,Competition_Events,7,FALSE)) | T12: =IF($D12="","",$N12&"//"&$P12) | U12: =IF($D12="","",IFERROR(CHOOSE(VLOOKUP($R12,Competition_Events,6,FALSE),SUBSTITUTE(O12,"点","")*1,SUBSTITUTE(O12,"m",".")*100,SUBSTITUTE(SUBSTITUTE("0:"&O12,"'",":"),"""",".")/"0:00:00.01"*-1,SUBSTITUTE(O12,"m",".")*100,SUBSTITUTE(SUBSTITUTE(O12,"'",":"),"""",".")/"0:00:00.01"*-1),-8640000)) | W12: =IF($D12="","",OFFSET('(2)出場選手'!$B$2,$A12,W$1)) | X12: =IF($D12="","",OFFSET('(2)出場選手'!$B$2,$A12,X$1)) | Y12: =IF($D12="","",OFFSET('(2)出場選手'!$B$2,$A12,Y$1)) | Z12: =IF($D12="","",OFFSET('(2)出場選手'!$B$2,$A12,Z$1))
A13: =TRUNC((ROWS($D$3:D13)-2)/Max_Entry_Count)+1 -> 4 | B13: =IF($A13>=ROWS(Entries)-2,"",IF(OFFSET('(2)出場選手'!$B$2,$A13,B$1+3*(MOD(ROWS($D$3:D13)-2,Max_Entry_Count)))="","",MOD(ROWS($D$3:D13)-2,Max_Entry_Count))) -> 0 | D13: =IF(OR($A13>=ROWS(Entries)-2,$B13=""),"",'(1)鑑'!$E$6&"-"&OFFSET('(2)出場選手'!$B$2,$A13,D$1)) -> Orcheria-4 | E13: =IF($D13="","",OFFSET('(2)出場選手'!$B$2,$A13,E$1)) -> 女子 | F13: =IF($D13="","",IF(OFFSET('(2)出場選手'!$B$2,$A13,F$1)="","",OFFSET('(2)出場選手'!$B$2,$A13,F$1))) -> 8104 | G13: =IF($D13="","",$W13&" "&$X13) -> 陽ノ下 菜津 | H13: =IF($D13="","",ASC(TRIM($Y13)&" "&TRIM($Z13))) -> ﾋﾉｼﾀ ﾅﾂ | I13: =IF($D13="","",IF(OFFSET('(2)出場選手'!$B$2,$A13,I$1)="","",OFFSET('(2)出場選手'!$B$2,$A13,I$1))) -> 中1 | J13: =IF($D13="","",IF(OFFSET('(2)出場選手'!$B$2,$A13,J$1)="",'(1)鑑'!$E$6,OFFSET('(2)出場選手'!$B$2,$A13,J$1))) -> Orcheria | K13: =IF($D13="","",TRIM(ASC(IF(OFFSET('(2)出場選手'!$B$2,$A13,K$1)="",'(1)鑑'!$E$7,OFFSET('(2)出場選手'!$B$2,$A13,K$1))))) -> ｵﾙｹﾘｱ | L13: =IF($D13="","",SUBSTITUTE(SUBSTITUTE(SUBSTITUTE(IF(OFFSET('(2)出場選手'!$B$2,$A13,L$1)="",'(1)鑑'!$E$8,OFFSET('(2)出場選手'!$B$2,$A13,L$1)),"県",""),"府",""),"東京都","東京")) -> 長崎 | M13: =IF($D13="","",IF(OFFSET('(2)出場選手'!$B$2,$A13,M$1)="","",OFFSET('(2)出場選手'!$B$2,$A13,M$1))) -> 41222 | N13: =IF($D13="","",OFFSET('(2)出場選手'!$B$2,$A13,N$1+3*$B13)) -> 女子100m | O13: =IF($D13="","",IF(OFFSET('(2)出場選手'!$B$2,$A13,O$1+3*$B13)="","",OFFSET('(2)出場選手'!$B$2,$A13,O$1+3*$B13))) -> 13.27 | P13: =IF($D13="","",IF(OFFSET('(2)出場選手'!$B$2,$A13,P$1+3*$B13)="","",OFFSET('(2)出場選手'!$B$2,$A13,P$1+3*$B13))) | Q13: =IF(D13="","",VLOOKUP(N13,OFFSET(Competition_Events,0,1),11,FALSE)*IF($S13="リレー",IF(COUNTIF($T$3:$T13,$T13)>1,0,1),1)) -> 900 | R13: =IF($D13="","",VLOOKUP($N13,OFFSET(Competition_Events,0,1),3,FALSE)) -> 15 | S13: =IF($D13="","",VLOOKUP($R13,Competition_Events,7,FALSE)) -> トラック | T13: =IF($D13="","",$N13&"//"&$P13) -> 女子100m// | U13: =IF($D13="","",IFERROR(CHOOSE(VLOOKUP($R13,Competition_Events,6,FALSE),SUBSTITUTE(O13,"点","")*1,SUBSTITUTE(O13,"m",".")*100,SUBSTITUTE(SUBSTITUTE("0:"&O13,"'",":"),"""",".")/"0:00:00.01"*-1,SUBSTITUTE(O13,"m",".")*100,SUBSTITUTE(SUBSTITUTE(O13,"'",":"),"""",".")/"0:00:00.01"*-1),-8640000)) -> -1327 | W13: =IF($D13="","",OFFSET('(2)出場選手'!$B$2,$A13,W$1)) -> 陽ノ下 | X13: =IF($D13="","",OFFSET('(2)出場選手'!$B$2,$A13,X$1)) -> 菜津 | Y13: =IF($D13="","",OFFSET('(2)出場選手'!$B$2,$A13,Y$1)) -> ヒノシタ | Z13: =IF($D13="","",OFFSET('(2)出場選手'!$B$2,$A13,Z$1)) -> ナツ
A14: =TRUNC((ROWS($D$3:D14)-2)/Max_Entry_Count)+1 -> 4 | B14: =IF($A14>=ROWS(Entries)-2,"",IF(OFFSET('(2)出場選手'!$B$2,$A14,B$1+3*(MOD(ROWS($D$3:D14)-2,Max_Entry_Count)))="","",MOD(ROWS($D$3:D14)-2,Max_Entry_Count))) -> 1 | D14: =IF(OR($A14>=ROWS(Entries)-2,$B14=""),"",'(1)鑑'!$E$6&"-"&OFFSET('(2)出場選手'!$B$2,$A14,D$1)) -> Orcheria-4 | E14: =IF($D14="","",OFFSET('(2)出場選手'!$B$2,$A14,E$1)) -> 女子 | F14: =IF($D14="","",IF(OFFSET('(2)出場選手'!$B$2,$A14,F$1)="","",OFFSET('(2)出場選手'!$B$2,$A14,F$1))) -> 8104 | G14: =IF($D14="","",$W14&" "&$X14) -> 陽ノ下 菜津 | H14: =IF($D14="","",ASC(TRIM($Y14)&" "&TRIM($Z14))) -> ﾋﾉｼﾀ ﾅﾂ | I14: =IF($D14="","",IF(OFFSET('(2)出場選手'!$B$2,$A14,I$1)="","",OFFSET('(2)出場選手'!$B$2,$A14,I$1))) -> 中1 | J14: =IF($D14="","",IF(OFFSET('(2)出場選手'!$B$2,$A14,J$1)="",'(1)鑑'!$E$6,OFFSET('(2)出場選手'!$B$2,$A14,J$1))) -> Orcheria | K14: =IF($D14="","",TRIM(ASC(IF(OFFSET('(2)出場選手'!$B$2,$A14,K$1)="",'(1)鑑'!$E$7,OFFSET('(2)出場選手'!$B$2,$A14,K$1))))) -> ｵﾙｹﾘｱ | L14: =IF($D14="","",SUBSTITUTE(SUBSTITUTE(SUBSTITUTE(IF(OFFSET('(2)出場選手'!$B$2,$A14,L$1)="",'(1)鑑'!$E$8,OFFSET('(2)出場選手'!$B$2,$A14,L$1)),"県",""),"府",""),"東京都","東京")) -> 長崎 | M14: =IF($D14="","",IF(OFFSET('(2)出場選手'!$B$2,$A14,M$1)="","",OFFSET('(2)出場選手'!$B$2,$A14,M$1))) -> 41222 | N14: =IF($D14="","",OFFSET('(2)出場選手'!$B$2,$A14,N$1+3*$B14)) -> 女子棒高跳 | O14: =IF($D14="","",IF(OFFSET('(2)出場選手'!$B$2,$A14,O$1+3*$B14)="","",OFFSET('(2)出場選手'!$B$2,$A14,O$1+3*$B14))) -> 2m90 | P14: =IF($D14="","",IF(OFFSET('(2)出場選手'!$B$2,$A14,P$1+3*$B14)="","",OFFSET('(2)出場選手'!$B$2,$A14,P$1+3*$B14))) | Q14: =IF(D14="","",VLOOKUP(N14,OFFSET(Competition_Events,0,1),11,FALSE)*IF($S14="リレー",IF(COUNTIF($T$3:$T14,$T14)>1,0,1),1)) -> 900 | R14: =IF($D14="","",VLOOKUP($N14,OFFSET(Competition_Events,0,1),3,FALSE)) -> 24 | S14: =IF($D14="","",VLOOKUP($R14,Competition_Events,7,FALSE)) -> フィールド | T14: =IF($D14="","",$N14&"//"&$P14) -> 女子棒高跳// | U14: =IF($D14="","",IFERROR(CHOOSE(VLOOKUP($R14,Competition_Events,6,FALSE),SUBSTITUTE(O14,"点","")*1,SUBSTITUTE(O14,"m",".")*100,SUBSTITUTE(SUBSTITUTE("0:"&O14,"'",":"),"""",".")/"0:00:00.01"*-1,SUBSTITUTE(O14,"m",".")*100,SUBSTITUTE(SUBSTITUTE(O14,"'",":"),"""",".")/"0:00:00.01"*-1),-8640000)) -> 290 | W14: =IF($D14="","",OFFSET('(2)出場選手'!$B$2,$A14,W$1)) -> 陽ノ下 | X14: =IF($D14="","",OFFSET('(2)出場選手'!$B$2,$A14,X$1)) -> 菜津 | Y14: =IF($D14="","",OFFSET('(2)出場選手'!$B$2,$A14,Y$1)) -> ヒノシタ | Z14: =IF($D14="","",OFFSET('(2)出場選手'!$B$2,$A14,Z$1)) -> ナツ
A15: =TRUNC((ROWS($D$3:D15)-2)/Max_Entry_Count)+1 -> 4 | B15: =IF($A15>=ROWS(Entries)-2,"",IF(OFFSET('(2)出場選手'!$B$2,$A15,B$1+3*(MOD(ROWS($D$3:D15)-2,Max_Entry_Count)))="","",MOD(ROWS($D$3:D15)-2,Max_Entry_Count))) | D15: =IF(OR($A15>=ROWS(Entries)-2,$B15=""),"",'(1)鑑'!$E$6&"-"&OFFSET('(2)出場選手'!$B$2,$A15,D$1)) | E15: =IF($D15="","",OFFSET('(2)出場選手'!$B$2,$A15,E$1)) | F15: =IF($D15="","",IF(OFFSET('(2)出場選手'!$B$2,$A15,F$1)="","",OFFSET('(2)出場選手'!$B$2,$A15,F$1))) | G15: =IF($D15="","",$W15&" "&$X15) | H15: =IF($D15="","",ASC(TRIM($Y15)&" "&TRIM($Z15))) | I15: =IF($D15="","",IF(OFFSET('(2)出場選手'!$B$2,$A15,I$1)="","",OFFSET('(2)出場選手'!$B$2,$A15,I$1))) | J15: =IF($D15="","",IF(OFFSET('(2)出場選手'!$B$2,$A15,J$1)="",'(1)鑑'!$E$6,OFFSET('(2)出場選手'!$B$2,$A15,J$1))) | K15: =IF($D15="","",TRIM(ASC(IF(OFFSET('(2)出場選手'!$B$2,$A15,K$1)="",'(1)鑑'!$E$7,OFFSET('(2)出場選手'!$B$2,$A15,K$1))))) | L15: =IF($D15="","",SUBSTITUTE(SUBSTITUTE(SUBSTITUTE(IF(OFFSET('(2)出場選手'!$B$2,$A15,L$1)="",'(1)鑑'!$E$8,OFFSET('(2)出場選手'!$B$2,$A15,L$1)),"県",""),"府",""),"東京都","東京")) | M15: =IF($D15="","",IF(OFFSET('(2)出場選手'!$B$2,$A15,M$1)="","",OFFSET('(2)出場選手'!$B$2,$A15,M$1))) | N15: =IF($D15="","",OFFSET('(2)出場選手'!$B$2,$A15,N$1+3*$B15)) | O15: =IF($D15="","",IF(OFFSET('(2)出場選手'!$B$2,$A15,O$1+3*$B15)="","",OFFSET('(2)出場選手'!$B$2,$A15,O$1+3*$B15))) | P15: =IF($D15="","",IF(OFFSET('(2)出場選手'!$B$2,$A15,P$1+3*$B15)="","",OFFSET('(2)出場選手'!$B$2,$A15,P$1+3*$B15))) | Q15: =IF(D15="","",VLOOKUP(N15,OFFSET(Competition_Events,0,1),11,FALSE)*IF($S15="リレー",IF(COUNTIF($T$3:$T15,$T15)>1,0,1),1)) | R15: =IF($D15="","",VLOOKUP($N15,OFFSET(Competition_Events,0,1),3,FALSE)) | S15: =IF($D15="","",VLOOKUP($R15,Competition_Events,7,FALSE)) | T15: =IF($D15="","",$N15&"//"&$P15) | U15: =IF($D15="","",IFERROR(CHOOSE(VLOOKUP($R15,Competition_Events,6,FALSE),SUBSTITUTE(O15,"点","")*1,SUBSTITUTE(O15,"m",".")*100,SUBSTITUTE(SUBSTITUTE("0:"&O15,"'",":"),"""",".")/"0:00:00.01"*-1,SUBSTITUTE(O15,"m",".")*100,SUBSTITUTE(SUBSTITUTE(O15,"'",":"),"""",".")/"0:00:00.01"*-1),-8640000)) | W15: =IF($D15="","",OFFSET('(2)出場選手'!$B$2,$A15,W$1)) | X15: =IF($D15="","",OFFSET('(2)出場選手'!$B$2,$A15,X$1)) | Y15: =IF($D15="","",OFFSET('(2)出場選手'!$B$2,$A15,Y$1)) | Z15: =IF($D15="","",OFFSET('(2)出場選手'!$B$2,$A15,Z$1))
... A503: =TRUNC((ROWS($D$3:D503)-2)/Max_Entry_Count)+1 -> 167 | B503: =IF($A503>=ROWS(Entries)-2,"",IF(OFFSET('(2)出場選手'!$B$2,$A503,B$1+3*(MOD(ROWS($D$3:D503)-2,Max_Entry_Count)))="","",MOD(ROWS($D$3:D503)-2,Max_Entry_Count))) | D503: =IF(OR($A503>=ROWS(Entries)-2,$B503=""),"",'(1)鑑'!$E$6&"-"&OFFSET('(2)出場選手'!$B$2,$A503,D$1)) | E503: =IF($D503="","",OFFSET('(2)出場選手'!$B$2,$A503,E$1)) | F503: =IF($D503="","",IF(OFFSET('(2)出場選手'!$B$2,$A503,F$1)="","",OFFSET('(2)出場選手'!$B$2,$A503,F$1))) | G503: =IF($D503="","",$W503&" "&$X503) | H503: =IF($D503="","",ASC(TRIM($Y503)&" "&TRIM($Z503))) | I503: =IF($D503="","",IF(OFFSET('(2)出場選手'!$B$2,$A503,I$1)="","",OFFSET('(2)出場選手'!$B$2,$A503,I$1))) | J503: =IF($D503="","",IF(OFFSET('(2)出場選手'!$B$2,$A503,J$1)="",'(1)鑑'!$E$6,OFFSET('(2)出場選手'!$B$2,$A503,J$1))) | K503: =IF($D503="","",TRIM(ASC(IF(OFFSET('(2)出場選手'!$B$2,$A503,K$1)="",'(1)鑑'!$E$7,OFFSET('(2)出場選手'!$B$2,$A503,K$1))))) | L503: =IF($D503="","",SUBSTITUTE(SUBSTITUTE(SUBSTITUTE(IF(OFFSET('(2)出場選手'!$B$2,$A503,L$1)="",'(1)鑑'!$E$8,OFFSET('(2)出場選手'!$B$2,$A503,L$1)),"県",""),"府",""),"東京都","東京")) | M503: =IF($D503="","",IF(OFFSET('(2)出場選手'!$B$2,$A503,M$1)="","",OFFSET('(2)出場選手'!$B$2,$A503,M$1))) | N503: =IF($D503="","",OFFSET('(2)出場選手'!$B$2,$A503,N$1+3*$B503)) | O503: =IF($D503="","",IF(OFFSET('(2)出場選手'!$B$2,$A503,O$1+3*$B503)="","",OFFSET('(2)出場選手'!$B$2,$A503,O$1+3*$B503))) | P503: =IF($D503="","",IF(OFFSET('(2)出場選手'!$B$2,$A503,P$1+3*$B503)="","",OFFSET('(2)出場選手'!$B$2,$A503,P$1+3*$B503))) | Q503: =IF(D503="","",VLOOKUP(N503,OFFSET(Competition_Events,0,1),11,FALSE)*IF($S503="リレー",IF(COUNTIF($T$3:$T503,$T503)>1,0,1),1)) | R503: =IF($D503="","",VLOOKUP($N503,OFFSET(Competition_Events,0,1),3,FALSE)) | S503: =IF($D503="","",VLOOKUP($R503,Competition_Events,7,FALSE)) | T503: =IF($D503="","",$N503&"//"&$P503) | U503: =IF($D503="","",IFERROR(CHOOSE(VLOOKUP($R503,Competition_Events,6,FALSE),SUBSTITUTE(O503,"点","")*1,SUBSTITUTE(O503,"m",".")*100,SUBSTITUTE(SUBSTITUTE("0:"&O503,"'",":"),"""",".")/"0:00:00.01"*-1,SUBSTITUTE(O503,"m",".")*100,SUBSTITUTE(SUBSTITUTE(O503,"'",":"),"""",".")/"0:00:00.01"*-1),-8640000)) | W503: =IF($D503="","",OFFSET('(2)出場選手'!$B$2,$A503,W$1)) | X503: =IF($D503="","",OFFSET('(2)出場選手'!$B$2,$A503,X$1)) | Y503: =IF($D503="","",OFFSET('(2)出場選手'!$B$2,$A503,Y$1)) | Z503: =IF($D503="","",OFFSET('(2)出場選手'!$B$2,$A503,Z$1))

Sheet （主催）種目リスト
B2: No. | C2: 種目名 | D2: 重複 | E2: 種目ID | F2: 性別チェック 有無 | G2: 競技種別 コード | H2: 競技種別 | I2: クラス | J2: 性別 | K2: 種目 | L2: 性別チェック 要否 | M2: エントリー料
B3: =IF(OR(J3="",K3="",H3="",M3=""),"",IF(D3<>"","",IF(M3<0,"",MAX($B$2:OFFSET(B3,-1,0))+1))) -> 1 | C3: =IF(OR(J3="",K3=""),"",I3&J3&K3) -> 男子100m | D3: =IF($C3="","",IF(COUNTIF($C$2:$C3,$C3)>1,"重複","")) | E3: =B3 -> 1 | F3: =IF(L3="",TRUE,IF(L3="不要",FALSE,TRUE)) -> TRUE | G3: =IF(E3="","",IFERROR(VLOOKUP(K3,Event_List,3,FALSE),-3)) -> 3 | H3: =IFERROR(VLOOKUP(K3,Event_List,2,FALSE),"") -> トラック | J3: 男子 | K3: 100m | M3: 900
B4: =IF(OR(J4="",K4="",H4="",M4=""),"",IF(D4<>"","",IF(M4<0,"",MAX($B$2:OFFSET(B4,-1,0))+1))) -> 2 | C4: =IF(OR(J4="",K4=""),"",I4&J4&K4) -> 男子200m | D4: =IF($C4="","",IF(COUNTIF($C$2:$C4,$C4)>1,"重複","")) | E4: =B4 -> 2 | F4: =IF(L4="",TRUE,IF(L4="不要",FALSE,TRUE)) -> TRUE | G4: =IF(E4="","",IFERROR(VLOOKUP(K4,Event_List,3,FALSE),-3)) -> 3 | H4: =IFERROR(VLOOKUP(K4,Event_List,2,FALSE),"") -> トラック | J4: 男子 | K4: 200m | M4: 900
B5: =IF(OR(J5="",K5="",H5="",M5=""),"",IF(D5<>"","",IF(M5<0,"",MAX($B$2:OFFSET(B5,-1,0))+1))) -> 3 | C5: =IF(OR(J5="",K5=""),"",I5&J5&K5) -> 男子400m | D5: =IF($C5="","",IF(COUNTIF($C$2:$C5,$C5)>1,"重複","")) | E5: =B5 -> 3 | F5: =IF(L5="",TRUE,IF(L5="不要",FALSE,TRUE)) -> TRUE | G5: =IF(E5="","",IFERROR(VLOOKUP(K5,Event_List,3,FALSE),-3)) -> 3 | H5: =IFERROR(VLOOKUP(K5,Event_List,2,FALSE),"") -> トラック | J5: 男子 | K5: 400m | M5: 900
B6: =IF(OR(J6="",K6="",H6="",M6=""),"",IF(D6<>"","",IF(M6<0,"",MAX($B$2:OFFSET(B6,-1,0))+1))) -> 4 | C6: =IF(OR(J6="",K6=""),"",I6&J6&K6) -> 男子800m | D6: =IF($C6="","",IF(COUNTIF($C$2:$C6,$C6)>1,"重複","")) | E6: =B6 -> 4 | F6: =IF(L6="",TRUE,IF(L6="不要",FALSE,TRUE)) -> TRUE | G6: =IF(E6="","",IFERROR(VLOOKUP(K6,Event_List,3,FALSE),-3)) -> 3 | H6: =IFERROR(VLOOKUP(K6,Event_List,2,FALSE),"") -> トラック | J6: 男子 | K6: 800m | M6: 900
B7: =IF(OR(J7="",K7="",H7="",M7=""),"",IF(D7<>"","",IF(M7<0,"",MAX($B$2:OFFSET(B7,-1,0))+1))) -> 5 | C7: =IF(OR(J7="",K7=""),"",I7&J7&K7) -> 男子3000m | D7: =IF($C7="","",IF(COUNTIF($C$2:$C7,$C7)>1,"重複","")) | E7: =B7 -> 5 | F7: =IF(L7="",TRUE,IF(L7="不要",FALSE,TRUE)) -> TRUE | G7: =IF(E7="","",IFERROR(VLOOKUP(K7,Event_List,3,FALSE),-3)) -> 3 | H7: =IFERROR(VLOOKUP(K7,Event_List,2,FALSE),"") -> トラック | J7: 男子 | K7: 3000m | M7: 900
B8: =IF(OR(J8="",K8="",H8="",M8=""),"",IF(D8<>"","",IF(M8<0,"",MAX($B$2:OFFSET(B8,-1,0))+1))) -> 6 | C8: =IF(OR(J8="",K8=""),"",I8&J8&K8) -> 男子110mH | D8: =IF($C8="","",IF(COUNTIF($C$2:$C8,$C8)>1,"重複","")) | E8: =B8 -> 6 | F8: =IF(L8="",TRUE,IF(L8="不要",FALSE,TRUE)) -> TRUE | G8: =IF(E8="","",IFERROR(VLOOKUP(K8,Event_List,3,FALSE),-3)) -> 3 | H8: =IFERROR(VLOOKUP(K8,Event_List,2,FALSE),"") -> トラック | J8: 男子 | K8: 110mH | M8: 900
B9: =IF(OR(J9="",K9="",H9="",M9=""),"",IF(D9<>"","",IF(M9<0,"",MAX($B$2:OFFSET(B9,-1,0))+1))) -> 7 | C9: =IF(OR(J9="",K9=""),"",I9&J9&K9) -> 男子300mH | D9: =IF($C9="","",IF(COUNTIF($C$2:$C9,$C9)>1,"重複","")) | E9: =B9 -> 7 | F9: =IF(L9="",TRUE,IF(L9="不要",FALSE,TRUE)) -> TRUE | G9: =IF(E9="","",IFERROR(VLOOKUP(K9,Event_List,3,FALSE),-3)) -> 3 | H9: =IFERROR(VLOOKUP(K9,Event_List,2,FALSE),"") -> トラック | J9: 男子 | K9: 300mH | M9: 900
B10: =IF(OR(J10="",K10="",H10="",M10=""),"",IF(D10<>"","",IF(M10<0,"",MAX($B$2:OFFSET(B10,-1,0))+1))) -> 8 | C10: =IF(OR(J10="",K10=""),"",I10&J10&K10) -> 男子4×100mR | D10: =IF($C10="","",IF(COUNTIF($C$2:$C10,$C10)>1,"重複","")) | E10: =B10 -> 8 | F10: =IF(L10="",TRUE,IF(L10="不要",FALSE,TRUE)) -> TRUE | G10: =IF(E10="","",IFERROR(VLOOKUP(K10,Event_List,3,FALSE),-3)) -> 3 | H10: =IFERROR(VLOOKUP(K10,Event_List,2,FALSE),"") -> リレー | J10: 男子 | K10: 4×100mR | M10: 1500
B11: =IF(OR(J11="",K11="",H11="",M11=""),"",IF(D11<>"","",IF(M11<0,"",MAX($B$2:OFFSET(B11,-1,0))+1))) -> 9 | C11: =IF(OR(J11="",K11=""),"",I11&J11&K11) -> 男子走高跳 | D11: =IF($C11="","",IF(COUNTIF($C$2:$C11,$C11)>1,"重複","")) | E11: =B11 -> 9 | F11: =IF(L11="",TRUE,IF(L11="不要",FALSE,TRUE)) -> TRUE | G11: =IF(E11="","",IFERROR(VLOOKUP(K11,Event_List,3,FALSE),-3)) -> 2 | H11: =IFERROR(VLOOKUP(K11,Event_List,2,FALSE),"") -> フィールド | J11: 男子 | K11: 走高跳 | M11: 900
B12: =IF(OR(J12="",K12="",H12="",M12=""),"",IF(D12<>"","",IF(M12<0,"",MAX($B$2:OFFSET(B12,-1,0))+1))) -> 10 | C12: =IF(OR(J12="",K12=""),"",I12&J12&K12) -> 男子棒高跳 | D12: =IF($C12="","",IF(COUNTIF($C$2:$C12,$C12)>1,"重複","")) | E12: =B12 -> 10 | F12: =IF(L12="",TRUE,IF(L12="不要",FALSE,TRUE)) -> TRUE | G12: =IF(E12="","",IFERROR(VLOOKUP(K12,Event_List,3,FALSE),-3)) -> 2 | H12: =IFERROR(VLOOKUP(K12,Event_List,2,FALSE),"") -> フィールド | J12: 男子 | K12: 棒高跳 | M12: 900
B13: =IF(OR(J13="",K13="",H13="",M13=""),"",IF(D13<>"","",IF(M13<0,"",MAX($B$2:OFFSET(B13,-1,0))+1))) -> 11 | C13: =IF(OR(J13="",K13=""),"",I13&J13&K13) -> 男子走幅跳 | D13: =IF($C13="","",IF(COUNTIF($C$2:$C13,$C13)>1,"重複","")) | E13: =B13 -> 11 | F13: =IF(L13="",TRUE,IF(L13="不要",FALSE,TRUE)) -> TRUE | G13: =IF(E13="","",IFERROR(VLOOKUP(K13,Event_List,3,FALSE),-3)) -> 2 | H13: =IFERROR(VLOOKUP(K13,Event_List,2,FALSE),"") -> フィールド | J13: 男子 | K13: 走幅跳 | M13: 900
B14: =IF(OR(J14="",K14="",H14="",M14=""),"",IF(D14<>"","",IF(M14<0,"",MAX($B$2:OFFSET(B14,-1,0))+1))) -> 12 | C14: =IF(OR(J14="",K14=""),"",I14&J14&K14) -> 男子砲丸投 | D14: =IF($C14="","",IF(COUNTIF($C$2:$C14,$C14)>1,"重複","")) | E14: =B14 -> 12 | F14: =IF(L14="",TRUE,IF(L14="不要",FALSE,TRUE)) -> TRUE | G14: =IF(E14="","",IFERROR(VLOOKUP(K14,Event_List,3,FALSE),-3)) -> 2 | H14: =IFERROR(VLOOKUP(K14,Event_List,2,FALSE),"") -> フィールド | J14: 男子 | K14: 砲丸投 | M14: 900
... B30: =IF(OR(J30="",K30="",H30="",M30=""),"",IF(D30<>"","",IF(M30<0,"",MAX($B$2:OFFSET(B30,-1,0))+1))) -> 28 | C30: =IF(OR(J30="",K30=""),"",I30&J30&K30) -> 女子四種競技 | D30: =IF($C30="","",IF(COUNTIF($C$2:$C30,$C30)>1,"重複","")) | E30: =B30 -> 28 | F30: =IF(L30="",TRUE,IF(L30="不要",FALSE,TRUE)) -> TRUE | G30: =IF(E30="","",IFERROR(VLOOKUP(K30,Event_List,3,FALSE),-3)) -> 1 | H30: =IFERROR(VLOOKUP(K30,Event_List,2,FALSE),"") -> 混成 | J30: 女子 | K30: 四種競技 | M30: 900
B31: =IF(OR(J31="",K31="",H31="",M31=""),"",IF(D31<>"","",IF(M31<0,"",MAX($B$2:OFFSET(B31,-1,0))+1))) | C31: =IF(OR(J31="",K31=""),"",I31&J31&K31) | D31: =IF($C31="","",IF(COUNTIF($C$2:$C31,$C31)>1,"重複","")) | E31: =B31 | F31: =IF(L31="",TRUE,IF(L31="不要",FALSE,TRUE)) -> TRUE | G31: =IF(E31="","",IFERROR(VLOOKUP(K31,Event_List,3,FALSE),-3)) | H31: =IFERROR(VLOOKUP(K31,Event_List,2,FALSE),"")
B32: =IF(OR(J32="",K32="",H32="",M32=""),"",IF(D32<>"","",IF(M32<0,"",MAX($B$2:OFFSET(B32,-1,0))+1))) | C32: =IF(OR(J32="",K32=""),"",I32&J32&K32) | D32: =IF($C32="","",IF(COUNTIF($C$2:$C32,$C32)>1,"重複","")) | E32: =B32 | F32: =IF(L32="",TRUE,IF(L32="不要",FALSE,TRUE)) -> TRUE | G32: =IF(E32="","",IFERROR(VLOOKUP(K32,Event_List,3,FALSE),-3)) | H32: =IFERROR(VLOOKUP(K32,Event_List,2,FALSE),"")
B33: =IF(OR(J33="",K33="",H33="",M33=""),"",IF(D33<>"","",IF(M33<0,"",MAX($B$2:OFFSET(B33,-1,0))+1))) | C33: =IF(OR(J33="",K33=""),"",I33&J33&K33) | D33: =IF($C33="","",IF(COUNTIF($C$2:$C33,$C33)>1,"重複","")) | E33: =B33 | F33: =IF(L33="",TRUE,IF(L33="不要",FALSE,TRUE)) -> TRUE | G33: =IF(E33="","",IFERROR(VLOOKUP(K33,Event_List,3,FALSE),-3)) | H33: =IFERROR(VLOOKUP(K33,Event_List,2,FALSE),"")
B34: =IF(OR(J34="",K34="",H34="",M34=""),"",IF(D34<>"","",IF(M34<0,"",MAX($B$2:OFFSET(B34,-1,0))+1))) | C34: =IF(OR(J34="",K34=""),"",I34&J34&K34) | D34: =IF($C34="","",IF(COUNTIF($C$2:$C34,$C34)>1,"重複","")) | E34: =B34 | F34: =IF(L34="",TRUE,IF(L34="不要",FALSE,TRUE)) -> TRUE | G34: =IF(E34="","",IFERROR(VLOOKUP(K34,Event_List,3,FALSE),-3)) | H34: =IFERROR(VLOOKUP(K34,Event_List,2,FALSE),"")
B35: =IF(OR(J35="",K35="",H35="",M35=""),"",IF(D35<>"","",IF(M35<0,"",MAX($B$2:OFFSET(B35,-1,0))+1))) | C35: =IF(OR(J35="",K35=""),"",I35&J35&K35) | D35: =IF($C35="","",IF(COUNTIF($C$2:$C35,$C35)>1,"重複","")) | E35: =B35 | F35: =IF(L35="",TRUE,IF(L35="不要",FALSE,TRUE)) -> TRUE | G35: =IF(E35="","",IFERROR(VLOOKUP(K35,Event_List,3,FALSE),-3)) | H35: =IFERROR(VLOOKUP(K35,Event_List,2,FALSE),"")
B36: =IF(OR(J36="",K36="",H36="",M36=""),"",IF(D36<>"","",IF(M36<0,"",MAX($B$2:OFFSET(B36,-1,0))+1))) | C36: =IF(OR(J36="",K36=""),"",I36&J36&K36) | D36: =IF($C36="","",IF(COUNTIF($C$2:$C36,$C36)>1,"重複","")) | E36: =B36 | F36: =IF(L36="",TRUE,IF(L36="不要",FALSE,TRUE)) -> TRUE | G36: =IF(E36="","",IFERROR(VLOOKUP(K36,Event_List,3,FALSE),-3)) | H36: =IFERROR(VLOOKUP(K36,Event_List,2,FALSE),"")
B37: =IF(OR(J37="",K37="",H37="",M37=""),"",IF(D37<>"","",IF(M37<0,"",MAX($B$2:OFFSET(B37,-1,0))+1))) | C37: =IF(OR(J37="",K37=""),"",I37&J37&K37) | D37: =IF($C37="","",IF(COUNTIF($C$2:$C37,$C37)>1,"重複","")) | E37: =B37 | F37: =IF(L37="",TRUE,IF(L37="不要",FALSE,TRUE)) -> TRUE | G37: =IF(E37="","",IFERROR(VLOOKUP(K37,Event_List,3,FALSE),-3)) | H37: =IFERROR(VLOOKUP(K37,Event_List,2,FALSE),"")
B38: =IF(OR(J38="",K38="",H38="",M38=""),"",IF(D38<>"","",IF(M38<0,"",MAX($B$2:OFFSET(B38,-1,0))+1))) | C38: =IF(OR(J38="",K38=""),"",I38&J38&K38) | D38: =IF($C38="","",IF(COUNTIF($C$2:$C38,$C38)>1,"重複","")) | E38: =B38 | F38: =IF(L38="",TRUE,IF(L38="不要",FALSE,TRUE)) -> TRUE | G38: =IF(E38="","",IFERROR(VLOOKUP(K38,Event_List,3,FALSE),-3)) | H38: =IFERROR(VLOOKUP(K38,Event_List,2,FALSE),"")
B39: =IF(OR(J39="",K39="",H39="",M39=""),"",IF(D39<>"","",IF(M39<0,"",MAX($B$2:OFFSET(B39,-1,0))+1))) | C39: =IF(OR(J39="",K39=""),"",I39&J39&K39) | D39: =IF($C39="","",IF(COUNTIF($C$2:$C39,$C39)>1,"重複","")) | E39: =B39 | F39: =IF(L39="",TRUE,IF(L39="不要",FALSE,TRUE)) -> TRUE | G39: =IF(E39="","",IFERROR(VLOOKUP(K39,Event_List,3,FALSE),-3)) | H39: =IFERROR(VLOOKUP(K39,Event_List,2,FALSE),"")
B40: =IF(OR(J40="",K40="",H40="",M40=""),"",IF(D40<>"","",IF(M40<0,"",MAX($B$2:OFFSET(B40,-1,0))+1))) | C40: =IF(OR(J40="",K40=""),"",I40&J40&K40) | D40: =IF($C40="","",IF(COUNTIF($C$2:$C40,$C40)>1,"重複","")) | E40: =B40 | F40: =IF(L40="",TRUE,IF(L40="不要",FALSE,TRUE)) -> TRUE | G40: =IF(E40="","",IFERROR(VLOOKUP(K40,Event_List,3,FALSE),-3)) | H40: =IFERROR(VLOOKUP(K40,Event_List,2,FALSE),"")
B41: =IF(OR(J41="",K41="",H41="",M41=""),"",IF(D41<>"","",IF(M41<0,"",MAX($B$2:OFFSET(B41,-1,0))+1))) | C41: =IF(OR(J41="",K41=""),"",I41&J41&K41) | D41: =IF($C41="","",IF(COUNTIF($C$2:$C41,$C41)>1,"重複","")) | E41: =B41 | F41: =IF(L41="",TRUE,IF(L41="不要",FALSE,TRUE)) -> TRUE | G41: =IF(E41="","",IFERROR(VLOOKUP(K41,Event_List,3,FALSE),-3)) | H41: =IFERROR(VLOOKUP(K41,Event_List,2,FALSE),"")
B42: =IF(OR(J42="",K42="",H42="",M42=""),"",IF(D42<>"","",IF(M42<0,"",MAX($B$2:OFFSET(B42,-1,0))+1))) | C42: =IF(OR(J42="",K42=""),"",I42&J42&K42) | D42: =IF($C42="","",IF(COUNTIF($C$2:$C42,$C42)>1,"重複","")) | E42: =B42 | F42: =IF(L42="",TRUE,IF(L42="不要",FALSE,TRUE)) -> TRUE | G42: =IF(E42="","",IFERROR(VLOOKUP(K42,Event_List,3,FALSE),-3)) | H42: =IFERROR(VLOOKUP(K42,Event_List,2,FALSE),"")
... B51: =IF(OR(J51="",K51="",H51="",M51=""),"",IF(D51<>"","",IF(M51<0,"",MAX($B$2:OFFSET(B51,-1,0))+1))) | C51: =IF(OR(J51="",K51=""),"",I51&J51&K51) | D51: =IF($C51="","",IF(COUNTIF($C$2:$C51,$C51)>1,"重複","")) | E51: =B51 | F51: =IF(L51="",TRUE,IF(L51="不要",FALSE,TRUE)) -> TRUE | G51: =IF(E51="","",IFERROR(VLOOKUP(K51,Event_List,3,FALSE),-3)) | H51: =IFERROR(VLOOKUP(K51,Event_List,2,FALSE),"")
B52: ▲▲▲

Sheet （主催）設定・リスト
B2: エントリー種目数 | C2: 3 | E2: 都道府県 | H2: 種目 | I2: 種別 | J2: エントリー形式
E3: 広島県 | H3: 50m | I3: トラック | J3: 3
E4: 鳥取県 | H4: 60m | I4: トラック | J4: 3
E5: 島根県 | H5: 80m | I5: トラック | J5: 3
E6: 岡山県 | H6: 100m | I6: トラック | J6: 3
E7: 山口県 | H7: 145m | I7: トラック | J7: 3
E8: 学連 | H8: 150m | I8: トラック | J8: 3
E9: 北海道 | H9: 200m | I9: トラック | J9: 3
E10: 青森県 | H10: 300m | I10: トラック | J10: 3
E11: 岩手県 | H11: 400m | I11: トラック | J11: 3
E12: 宮城県 | H12: 800m | I12: トラック | J12: 3
E13: 秋田県 | H13: 1500m | I13: トラック | J13: 3
E14: 山形県 | H14: 2000m | I14: トラック | J14: 3
... E50: 沖縄県 | H50: こん棒投 | I50: フィールド | J50: 2
H51: コンバインドＡ | I51: 混成 | J51: 1
H52: コンバインドB | I52: 混成 | J52: 1
H53: 四種競技 | I53: 混成 | J53: 1
H54: 五種競技 | I54: 混成 | J54: 1
H55: 七種競技 | I55: 混成 | J55: 1
H56: 八種競技 | I56: 混成 | J56: 1
H57: 十種競技 | I57: 混成 | J57: 1
H58: 十四種競技 | I58: 混成 | J58: 1
H59: 二十種競技 | I59: 混成 | J59: 1
H60: 2km | I60: 道路 | J60: 0
H61: 3km | I61: 道路 | J61: 0
H62: 5km | I62: 道路 | J62: 0
... H72: 50kmW | I72: 道路 | J72: 0
H73: ★
